<mujoco model="base">
  <compiler angle="radian" meshdir="meshes/" inertiagrouprange="0 0" autolimits="true" />
  <option impratio="20" cone="elliptic" density="1.2" viscosity="0.00002" timestep="0.002" />
  <size nconmax="5000" njmax="5000" />

  <asset>
  <material name="robot0_white" rgba="1 1 1 1" />
    <material name="robot0_gray" rgba="0.753 0.753 0.753 1" />
    <material name="robot0_black" rgba="0.149 0.149 0.149 1" />

    <mesh name="robot0_link_base" file="/Users/jaiselsingh/Desktop/robosuite/robosuite/models/assets/robots/xarm7/meshes/link_base.stl" />
    <mesh name="robot0_link1" file="/Users/jaiselsingh/Desktop/robosuite/robosuite/models/assets/robots/xarm7/meshes/link1.stl" />
    <mesh name="robot0_link2" file="/Users/jaiselsingh/Desktop/robosuite/robosuite/models/assets/robots/xarm7/meshes/link2.stl" />
    <mesh name="robot0_link3" file="/Users/jaiselsingh/Desktop/robosuite/robosuite/models/assets/robots/xarm7/meshes/link3.stl" />
    <mesh name="robot0_link4" file="/Users/jaiselsingh/Desktop/robosuite/robosuite/models/assets/robots/xarm7/meshes/link4.stl" />
    <mesh name="robot0_link5" file="/Users/jaiselsingh/Desktop/robosuite/robosuite/models/assets/robots/xarm7/meshes/link5.stl" />
    <mesh name="robot0_link6" file="/Users/jaiselsingh/Desktop/robosuite/robosuite/models/assets/robots/xarm7/meshes/link6.stl" />
    <mesh name="robot0_link7" file="/Users/jaiselsingh/Desktop/robosuite/robosuite/models/assets/robots/xarm7/meshes/link7.stl" />
    <mesh name="robot0_end_tool" file="/Users/jaiselsingh/Desktop/robosuite/robosuite/models/assets/robots/xarm7/meshes/end_tool.stl" />
  <material name="gripper0_white" rgba="1 1 1 1" />
    <material name="gripper0_black" rgba="0.149 0.149 0.149 1" />

    <mesh name="gripper0_base_link" file="/Users/jaiselsingh/Desktop/robosuite/robosuite/models/assets/grippers/meshes/xarm7_gripper/base_link.stl" />
    <mesh name="gripper0_left_outer_knuckle" file="/Users/jaiselsingh/Desktop/robosuite/robosuite/models/assets/grippers/meshes/xarm7_gripper/left_outer_knuckle.stl" />
    <mesh name="gripper0_left_finger" file="/Users/jaiselsingh/Desktop/robosuite/robosuite/models/assets/grippers/meshes/xarm7_gripper/left_finger.stl" />
    <mesh name="gripper0_left_inner_knuckle" file="/Users/jaiselsingh/Desktop/robosuite/robosuite/models/assets/grippers/meshes/xarm7_gripper/left_inner_knuckle.stl" />
    <mesh name="gripper0_right_outer_knuckle" file="/Users/jaiselsingh/Desktop/robosuite/robosuite/models/assets/grippers/meshes/xarm7_gripper/right_outer_knuckle.stl" />
    <mesh name="gripper0_right_finger" file="/Users/jaiselsingh/Desktop/robosuite/robosuite/models/assets/grippers/meshes/xarm7_gripper/right_finger.stl" />
    <mesh name="gripper0_right_inner_knuckle" file="/Users/jaiselsingh/Desktop/robosuite/robosuite/models/assets/grippers/meshes/xarm7_gripper/right_inner_knuckle.stl" />
  <texture builtin="gradient" height="256" rgb1=".9 .9 1." rgb2=".2 .3 .4" type="skybox" width="256" />
    <texture file="/Users/jaiselsingh/Desktop/robosuite/robosuite/models/assets/arenas/../textures/light-gray-floor-tile.png" type="2d" name="texplane" />
    <material name="floorplane" reflectance="0.01" shininess="0.0" specular="0.0" texrepeat="2 2" texture="texplane" texuniform="true" />
    
    <texture file="/Users/jaiselsingh/Desktop/robosuite/robosuite/models/assets/arenas/../textures/ceramic.png" type="cube" name="tex-ceramic" />
    <material name="table_ceramic" reflectance="0.0" shininess="0.0" specular="0.2" texrepeat="1 1" texture="tex-ceramic" />
    
    <texture file="/Users/jaiselsingh/Desktop/robosuite/robosuite/models/assets/arenas/../textures/steel-brushed.png" type="cube" name="tex-steel-brushed" />
    <material name="table_legs_metal" reflectance="0.8" shininess="0.8" texrepeat="1 1" texture="tex-steel-brushed" />
    
    <texture file="/Users/jaiselsingh/Desktop/robosuite/robosuite/models/assets/arenas/../textures/light-gray-plaster.png" type="2d" name="tex-light-gray-plaster" />
    <material name="walls_mat" reflectance="0.0" shininess="0.1" specular="0.1" texrepeat="3 3" texture="tex-light-gray-plaster" texuniform="true" />
    
    <texture name="textable" builtin="flat" height="512" width="512" rgb1="0.5 0.5 0.5" rgb2="0.5 0.5 0.5" />
    <material name="table_mat" texture="textable" />

  </asset>

  <visual>
    <map znear="0.001" />
  </visual>

  <actuator>
  <motor ctrllimited="true" ctrlrange="-80.0 80.0" joint="robot0_joint1" name="robot0_torq_j1" />
    <motor ctrllimited="true" ctrlrange="-80.0 80.0" joint="robot0_joint2" name="robot0_torq_j2" />
    <motor ctrllimited="true" ctrlrange="-80.0 80.0" joint="robot0_joint3" name="robot0_torq_j3" />
    <motor ctrllimited="true" ctrlrange="-80.0 80.0" joint="robot0_joint4" name="robot0_torq_j4" />
    <motor ctrllimited="true" ctrlrange="-80.0 80.0" joint="robot0_joint5" name="robot0_torq_j5" />
    <motor ctrllimited="true" ctrlrange="-80.0 80.0" joint="robot0_joint6" name="robot0_torq_j6" />
    <motor ctrllimited="true" ctrlrange="-80.0 80.0" joint="robot0_joint7" name="robot0_torq_j7" />
  <general name="gripper0_fingers_actuator" tendon="gripper0_split" biastype="affine" forcerange="-50 50" ctrlrange="0 255" gainprm="0.333" biasprm="0 -100 -10" />
  </actuator>

  <worldbody>
  <body name="robot0_base" pos="0.0 0.0 0.0">
      
      <camera mode="fixed" name="robot0_robotview" pos="1.0 0 0.4" quat="0.653 0.271 0.271 0.653" />
      
      

      <inertial pos="-0.021131 -0.0016302 0.056488" quat="0.696843 0.20176 0.10388 0.680376" mass="0.88556" diaginertia="0.00382023 0.00335282 0.00167725" />
      <geom mesh="robot0_link_base" type="mesh" material="robot0_white" group="1" name="robot0_g0_vis" />
      <body name="robot0_link1" pos="0 0 0.267">
	<site name="robot0_right_center" pos="0 0 0" size="0.01" rgba="1 0.3 0.3 1" group="2" />
        <inertial pos="-0.0002 0.02905 -0.01233" quat="0.978953 -0.202769 -0.00441617 -0.0227264" mass="2.382" diaginertia="0.00569127 0.00533384 0.00293865" />
        <joint name="robot0_joint1" axis="0 0 1" range="-6.28319 6.28319" frictionloss="1" damping="0.1" armature="5.0" />
        <geom mesh="robot0_link1" type="mesh" material="robot0_white" group="1" name="robot0_g1_vis" />
        <body name="robot0_link2" quat="1 -1 0 0">
          <inertial pos="0.00022 -0.12856 0.01735" quat="0.50198 0.86483 -0.00778841 0.00483285" mass="1.869" diaginertia="0.00959898 0.00937717 0.00201315" />
          <joint name="robot0_joint2" axis="0 0 1" frictionloss="1" range="-2.059 2.0944" damping="0.1" armature="2.5" />
          <geom mesh="robot0_link2" type="mesh" material="robot0_white" group="1" name="robot0_g2_vis" />
          <body name="robot0_link3" pos="0 -0.293 0" quat="1 1 0 0">
            <inertial pos="0.0466 -0.02463 -0.00768" quat="0.913819 0.289775 0.281481 -0.0416455" mass="1.6383" diaginertia="0.00351721 0.00294089 0.00195868" />
            <joint name="robot0_joint3" axis="0 0 1" range="-6.28319 6.28319" frictionloss="1" damping="0.1" armature="1.6666666666666667" />
            <geom mesh="robot0_link3" type="mesh" material="robot0_white" group="1" name="robot0_g3_vis" />
            <body name="robot0_link4" pos="0.0525 0 0" quat="1 1 0 0">
              <inertial pos="0.07047 -0.11575 0.012" quat="0.422108 0.852026 -0.126025 0.282832" mass="1.7269" diaginertia="0.00657137 0.00647948 0.00186763" />
              <joint name="robot0_joint4" axis="0 0 1" frictionloss="1" range="-0.19198 3.927" damping="0.1" armature="1.25" />
              <geom mesh="robot0_link4" type="mesh" material="robot0_white" group="1" name="robot0_g4_vis" />
              <body name="robot0_link5" pos="0.0775 -0.3425 0" quat="1 1 0 0">
                <inertial pos="-0.00032 0.01604 -0.026" quat="0.999311 -0.0304457 0.000577067 0.0212082" mass="1.3203" diaginertia="0.00534729 0.00499076 0.0013489" />
                <joint name="robot0_joint5" axis="0 0 1" range="-6.28319 6.28319" frictionloss="1" damping="0.1" armature="1.0" />
                <geom mesh="robot0_link5" type="mesh" material="robot0_white" group="1" name="robot0_g5_vis" />
                <body name="robot0_link6" quat="1 1 0 0">
                  <inertial pos="0.06469 0.03278 0.02141" quat="-0.217672 0.772419 0.16258 0.574069" mass="1.325" diaginertia="0.00245421 0.00221646 0.00107273" />
                  <joint name="robot0_joint6" axis="0 0 1" frictionloss="1" range="-1.69297 3.14159" damping="0.01" armature="0.8333333333333334" />
                  <geom mesh="robot0_link6" type="mesh" material="robot0_white" group="1" name="robot0_g6_vis" />
                  <body name="robot0_link7" pos="0.076 0.097 0" quat="1 -1 0 0">
                    <inertial pos="0 -0.00677 -0.01098" quat="0.487612 0.512088 -0.512088 0.487612" mass="0.17" diaginertia="0.000132176 9.3e-05 5.85236e-05" />
                    <joint name="robot0_joint7" axis="0 0 1" range="-6.28319 6.28319" frictionloss="1" damping="0.01" armature="0.7142857142857143" />
                    

		    <body name="robot0_right_hand" pos="0.0 0.0 -0.027" quat="0 0 0 1">
			
			
			

			
			<site name="robot0_ee" pos="0 0 0" size="0.01 0.01 0.01" rgba="0 0 1 1" type="sphere" group="1" />
			<site name="robot0_ee_x" pos="0 0 0" size="0.005 .1" quat="0.707105 0.707108 0 0 " rgba="1 0 0 0" type="cylinder" />
			<site name="robot0_ee_z" pos="0 0 0" size="0.005 .1" quat="0.707105 0 0 0.707108" rgba="0 0 1 0" type="cylinder" />
			<site name="robot0_ee_y" pos="0 0 0" size="0.005 .1" quat="0.707105 0 0.707108 0 " rgba="0 1 0 0" type="cylinder" />
			
			<camera mode="fixed" name="robot0_eye_in_hand" pos="0.05 0 0" quat="0 0.707108 0.707108 0" fovy="75" />
			
		    <body name="gripper0_xarm_gripper_base_link">
      <inertial pos="-0.00065489 -0.0018497 0.048028" quat="0.997403 -0.0717512 -0.0061836 0.000477479" mass="0.54156" diaginertia="0.000471093 0.000332307 0.000254799" />
      <geom mesh="gripper0_base_link" material="gripper0_white" type="mesh" group="1" name="gripper0_g0_vis" />
      <body name="gripper0_left_outer_knuckle" pos="0 0.035 0.059098">
        <inertial pos="0 0.021559 0.015181" quat="0.47789 0.87842 0 0" mass="0.033618" diaginertia="1.9111e-05 1.79089e-05 1.90167e-06" />
        <joint name="gripper0_left_driver_joint" axis="1 0 0" frictionloss="1" armature="0.005" damping="0.1" solreflimit="0.005 1" />
        <geom material="gripper0_black" mesh="gripper0_left_outer_knuckle" type="mesh" group="1" name="gripper0_g1_vis" />
        <body name="gripper0_left_finger" pos="0 0.035465 0.042039">
          <inertial pos="0 -0.016413 0.029258" quat="0.697634 0.115353 -0.115353 0.697634" mass="0.048304" diaginertia="1.88037e-05 1.7493e-05 3.56792e-06" />
          <joint name="gripper0_left_finger_joint" axis="-1 0 0" armature="0.1" frictionloss="1" solreflimit="0.005 1" />
          <geom material="gripper0_black" mesh="gripper0_left_finger" type="mesh" contype="0" conaffinity="0" group="1" name="gripper0_g2_vis" />
          <geom name="gripper0_left_finger_pad_1" pos="0 -0.024003 0.032" type="box" friction="0.7" solimp="0.95 0.99 0.001" solref="0.004 1" mass="0" priority="1" size="0.015 0.002 0.0095" rgba="0 0 0.5 1" />
          <geom name="gripper0_left_finger_pad_2" pos="0 -0.024003 0.050" type="box" friction="0.6" solimp="0.95 0.99 0.001" solref="0.004 1" mass="0" priority="1" size="0.015 0.002 0.0095" rgba="0 0 0.5 1" />
        </body>
      </body>
      <body name="gripper0_left_inner_knuckle" pos="0 0.02 0.074098">
        <inertial pos="1.86601e-06 0.0220468 0.0261335" quat="0.664139 -0.242732 0.242713 0.664146" mass="0.0230126" diaginertia="8.34216e-06 6.0949e-06 2.75601e-06" />
        <joint name="gripper0_left_inner_knuckle_joint" axis="1 0 0" armature="0.1" frictionloss="1" stiffness="0.05" springref="2.62" damping="0.00125" />
        <geom material="gripper0_black" mesh="gripper0_left_inner_knuckle" type="mesh" group="1" name="gripper0_g3_vis" />
      </body>
      <body name="gripper0_right_outer_knuckle" pos="0 -0.035 0.059098">
        <inertial pos="0 -0.021559 0.015181" quat="0.87842 0.47789 0 0" mass="0.033618" diaginertia="1.9111e-05 1.79089e-05 1.90167e-06" />
        <joint name="gripper0_right_driver_joint" axis="-1 0 0" frictionloss="1" armature="0.005" damping="0.1" solreflimit="0.005 1" />
        <geom material="gripper0_black" mesh="gripper0_right_outer_knuckle" type="mesh" group="1" name="gripper0_g4_vis" />
        <body name="gripper0_right_finger" pos="0 -0.035465 0.042039">
          <inertial pos="0 0.016413 0.029258" quat="0.697634 -0.115356 0.115356 0.697634" mass="0.048304" diaginertia="1.88038e-05 1.7493e-05 3.56779e-06" />
          <joint name="gripper0_right_finger_joint" axis="1 0 0" armature="0.1" frictionloss="1" solreflimit="0.005 1" />
          <geom material="gripper0_black" mesh="gripper0_right_finger" type="mesh" contype="0" conaffinity="0" group="1" name="gripper0_g5_vis" />
          <geom name="gripper0_right_finger_pad_1" pos="0 0.024003 0.032" type="box" friction="0.7" solimp="0.95 0.99 0.001" solref="0.004 1" mass="0" priority="1" size="0.015 0.002 0.0095" rgba="0 0 0.5 1" />
          <geom name="gripper0_right_finger_pad_2" pos="0 0.024003 0.050" type="box" friction="0.6" solimp="0.95 0.99 0.001" solref="0.004 1" mass="0" priority="1" size="0.015 0.002 0.0095" rgba="0 0 0.5 1" />
          <site name="gripper0_ft_frame" pos="0 0 0" size="0.01 0.01 0.01" rgba="1 0 0 1" type="sphere" group="1" />
        </body>
      </body>
      <body name="gripper0_right_inner_knuckle" pos="0 -0.02 0.074098">
        <inertial pos="1.866e-06 -0.022047 0.026133" quat="0.66415 0.242702 -0.242721 0.664144" mass="0.023013" diaginertia="8.34209e-06 6.0949e-06 2.75601e-06" />
        <joint name="gripper0_right_inner_knuckle_joint" axis="-1 0 0" armature="0.1" frictionloss="1" stiffness="0.05" springref="2.62" damping="0.00125" />
        <geom material="gripper0_black" mesh="gripper0_right_inner_knuckle" type="mesh" group="1" name="gripper0_g6_vis" />
      </body>
      <body name="gripper0_eef" pos="0 0 0.097" quat="1 0 0 0">
	<site name="gripper0_grip_site" pos="0 0 0.05" size="0.01 0.01 0.01" rgba="1 0 0 0.5" type="sphere" group="1" />
	<site name="gripper0_ee_x" pos="0.1 0 0" size="0.005 .1" quat="0.707105  0 0.707108 0 " rgba="1 0 0 0" type="cylinder" group="1" />
	<site name="gripper0_ee_y" pos="0 0.1 0" size="0.005 .1" quat="0.707105 0.707108 0 0" rgba="0 1 0 0" type="cylinder" group="1" />
	<site name="gripper0_ee_z" pos="0 0 0.1" size="0.005 .1" quat="1 0 0 0" rgba="0 0 1 0" type="cylinder" group="1" />
	
	<site name="gripper0_grip_site_cylinder" pos="0 0 0" size="0.005 10" rgba="0 1 0 0.3" type="cylinder" group="1" />
      </body>
    </body>
  </body>
                  </body>
                </body>
              </body>
            </body>
          </body>
        </body>
      </body>
    </body>
  <geom condim="3" group="1" material="floorplane" name="floor" pos="0.8 0.0 0.0" size="3 3 .125" type="plane" />
    
    <geom pos="-0.44999999999999996 2.25 1.5" quat="0.6532815 0.6532815 0.2705981 0.2705981" size="1.06 1.5 0.01" type="box" conaffinity="0" contype="0" group="1" name="wall_leftcorner_visual" material="walls_mat" />
    <geom pos="-0.44999999999999996 -2.25 1.5" quat="0.6532815 0.6532815 -0.2705981 -0.2705981" size="1.06 1.5 0.01" type="box" conaffinity="0" contype="0" group="1" name="wall_rightcorner_visual" material="walls_mat" />
    <geom pos="2.05 3.0 1.5" quat="0.7071 0.7071 0 0" size="1.75 1.5 0.01" type="box" conaffinity="0" contype="0" group="1" name="wall_left_visual" material="walls_mat" />
    <geom pos="2.05 -3.0 1.5" quat="0.7071 -0.7071 0 0" size="1.75 1.5 0.01" type="box" conaffinity="0" contype="0" group="1" name="wall_right_visual" material="walls_mat" />
    <geom pos="-1.2 0.0 1.5" quat="0.5 0.5 0.5 0.5" size="1.5 1.5 0.01" type="box" conaffinity="0" contype="0" group="1" name="wall_rear_visual" material="walls_mat" />
    <geom pos="3.8 0.0 1.5" quat="0.5 0.5 -0.5 -0.5" size="3 1.5 0.01" type="box" conaffinity="0" contype="0" group="1" name="wall_front_visual" material="walls_mat" />
    
    <body name="table" pos="0.8 0.0 0.775">
      <geom pos="0 0 0" size="0.4 0.4 0.025" type="box" group="0" name="table_collision" friction="1 0.005 0.0001" rgba="0.5 0.5 0 1" />
      <geom pos="0 0 0" size="0.4 0.4 0.025" type="box" conaffinity="0" contype="0" group="1" name="table_visual" material="table_ceramic" />
      <site pos="0.0 0.0 0.025" name="table_top" size="0.001 0.001 0.001" rgba="0 0 0 0" />
      
      <geom pos="0.30000000000000004 0.30000000000000004 -0.3875" size="0.025 0.3875" type="cylinder" conaffinity="0" contype="0" group="1" name="table_leg1_visual" material="table_legs_metal" />
      <geom pos="-0.30000000000000004 0.30000000000000004 -0.3875" size="0.025 0.3875" type="cylinder" conaffinity="0" contype="0" group="1" name="table_leg2_visual" material="table_legs_metal" />
      <geom pos="-0.30000000000000004 -0.30000000000000004 -0.3875" size="0.025 0.3875" type="cylinder" conaffinity="0" contype="0" group="1" name="table_leg3_visual" material="table_legs_metal" />
      <geom pos="0.30000000000000004 -0.30000000000000004 -0.3875" size="0.025 0.3875" type="cylinder" conaffinity="0" contype="0" group="1" name="table_leg4_visual" material="table_legs_metal" />
    </body>
    <light pos="1.8 1.0 1.5" dir="-0.2 -0.2 -1" specular="0.3 0.3 0.3" directional="true" castshadow="false" />
    
    <camera mode="fixed" name="frontview" pos="2.4000000000000004 0.0 1.45" quat="0.56 0.43 0.43 0.56" />
    
    <camera mode="fixed" name="birdview" pos="0.6000000000000001 0.0 3.0" quat="0.7071 0 0 0.7071" />
    
    <camera mode="fixed" name="agentview" pos="1.3 0.0 1.35" quat="0.653 0.271 0.271 0.653" />
    
    <camera mode="fixed" name="sideview" pos="0.7434822540668289 1.2761224129427358 1.4879572214102434" quat="0.009905065491771751 0.006877963156909582 0.5912228352893879 0.806418094001364" />
  <body mocap="true" pos="0.8 0.0 -1.0" name="left_eef_target"><geom rgba="0.898 0.420 0.435 0.5" conaffinity="0" contype="0" type="box" size="0.05 0.05 0.05" pos="0 0 0" group="2" name="left_eef_target_box" /><geom rgba="0.898 0.420 0.435 0.8" conaffinity="0" contype="0" type="sphere" size="0.01" pos="0 0 0" group="2" name="left_eef_target_sphere" /></body><body mocap="true" pos="0.8 0.0 -1.0" name="right_eef_target"><geom rgba="0.208 0.314 0.439 0.5" conaffinity="0" contype="0" type="box" size="0.05 0.05 0.05" pos="0 0 0" group="2" name="right_eef_target_box" /><geom rgba="0.208 0.314 0.439 0.8" conaffinity="0" contype="0" type="sphere" size="0.01" pos="0 0 0" group="2" name="right_eef_target_sphere" /></body><body pos="0.8 0.0 0.8400000000000001" name="can_main"><geom rgba="0.5 0 0 1" margin="0.001" density="1000" friction="1 0.01 0.001" solref="0.01 0.5" solimp="0.9 0.95 0.001" type="cylinder" size="0.04 0.048" pos="0 0 0" group="0" name="can_g0" /><geom conaffinity="0" contype="0" mass="1e-8" rgba="0.9 0.2 0.2 1.0" type="cylinder" size="0.04 0.048" pos="0 0 0" group="1" name="can_g0_vis" /><joint type="free" damping="0.0001" name="can_joint0" /><site type="sphere" group="0" pos="0 0 0" size="0.002 0.002 0.002" rgba="1 0 0 1" name="can_default_site" /></body><body pos="0.7000000000000001 0.1 0.8400000000000001" name="box_main"><geom rgba="0.5 0 0 1" density="1000" friction="1 0.005 0.0001" solref="0.02 1.0" solimp="0.9 0.95 0.001" type="box" size="0.04 0.04 0.02" pos="0 0 0" group="0" name="box_g0" /><geom conaffinity="0" contype="0" mass="1e-8" rgba="0.2 0.6 0.9 1.0" type="box" size="0.04 0.04 0.02" pos="0 0 0" group="1" name="box_g0_vis" /><joint type="free" name="box_joint0" /><site type="sphere" group="0" pos="0 0 0" size="0.002 0.002 0.002" rgba="1 0 0 1" name="box_default_site" /></body></worldbody>

  <equality>
  <connect anchor="0 0.015 0.015" body1="gripper0_right_finger" body2="gripper0_right_inner_knuckle" solref="0.005 1" />
    <connect anchor="0 -0.015 0.015" body1="gripper0_left_finger" body2="gripper0_left_inner_knuckle" solref="0.005 1" />
    <joint joint1="gripper0_left_driver_joint" joint2="gripper0_right_driver_joint" polycoef="0 1 0 0 0" solref="0.005 1" />
  </equality>
<sensor><force name="gripper0_force_ee" site="gripper0_ft_frame" />
    <torque name="gripper0_torque_ee" site="gripper0_ft_frame" />
  </sensor><tendon><fixed name="gripper0_split">
      <joint joint="gripper0_right_driver_joint" coef="0.5" />
      <joint joint="gripper0_left_driver_joint" coef="0.5" />
    </fixed>
  </tendon><contact><exclude body1="gripper0_right_inner_knuckle" body2="gripper0_right_outer_knuckle" />
    <exclude body1="gripper0_right_inner_knuckle" body2="gripper0_right_finger" />
    <exclude body1="gripper0_left_inner_knuckle" body2="gripper0_left_outer_knuckle" />
    <exclude body1="gripper0_left_inner_knuckle" body2="gripper0_left_finger" />
    <exclude body1="gripper0_left_inner_knuckle" body2="gripper0_xarm_gripper_base_link" />
    <exclude body1="gripper0_right_inner_knuckle" body2="gripper0_xarm_gripper_base_link" />
    <exclude body1="gripper0_left_outer_knuckle" body2="gripper0_xarm_gripper_base_link" />
    <exclude body1="gripper0_right_outer_knuckle" body2="gripper0_xarm_gripper_base_link" />
  </contact></mujoco>